2019-08-02 19:28:09,386 [ERROR]  Unable to start server
Traceback (most recent call last):
  File "uvloop/loop.pyx", line 1112, in uvloop.loop.Loop._create_server
  File "uvloop/handles/streamserver.pyx", line 58, in uvloop.loop.UVStreamServer.listen
  File "uvloop/handles/streamserver.pyx", line 95, in uvloop.loop.UVStreamServer._fatal_error
OSError: [Errno 48] Address already in use

During handling of the above exception, another exception occurred:

Traceback (most recent call last):
  File "/anaconda3/envs/friday/lib/python3.6/site-packages/sanic/server.py", line 745, in serve
    http_server = loop.run_until_complete(server_coroutine)
  File "uvloop/loop.pyx", line 1451, in uvloop.loop.Loop.run_until_complete
  File "uvloop/loop.pyx", line 1684, in create_server
  File "uvloop/loop.pyx", line 1116, in uvloop.loop.Loop._create_server
OSError: [Errno 48] error while attempting to bind on address ('0.0.0.0', 5005): address already in use
2019-08-02 19:28:25,505 [ERROR]  Unable to start server
Traceback (most recent call last):
  File "uvloop/loop.pyx", line 1112, in uvloop.loop.Loop._create_server
  File "uvloop/handles/streamserver.pyx", line 58, in uvloop.loop.UVStreamServer.listen
  File "uvloop/handles/streamserver.pyx", line 95, in uvloop.loop.UVStreamServer._fatal_error
OSError: [Errno 48] Address already in use

During handling of the above exception, another exception occurred:

Traceback (most recent call last):
  File "/anaconda3/envs/friday/lib/python3.6/site-packages/sanic/server.py", line 745, in serve
    http_server = loop.run_until_complete(server_coroutine)
  File "uvloop/loop.pyx", line 1451, in uvloop.loop.Loop.run_until_complete
  File "uvloop/loop.pyx", line 1684, in create_server
  File "uvloop/loop.pyx", line 1116, in uvloop.loop.Loop._create_server
OSError: [Errno 48] error while attempting to bind on address ('0.0.0.0', 5005): address already in use
2019-11-08 00:44:13,947 [ERROR]  Unable to start server
Traceback (most recent call last):
  File "uvloop/loop.pyx", line 1112, in uvloop.loop.Loop._create_server
  File "uvloop/handles/streamserver.pyx", line 58, in uvloop.loop.UVStreamServer.listen
  File "uvloop/handles/streamserver.pyx", line 95, in uvloop.loop.UVStreamServer._fatal_error
OSError: [Errno 48] Address already in use

During handling of the above exception, another exception occurred:

Traceback (most recent call last):
  File "/anaconda3/envs/friday/lib/python3.6/site-packages/sanic/server.py", line 745, in serve
    http_server = loop.run_until_complete(server_coroutine)
  File "uvloop/loop.pyx", line 1451, in uvloop.loop.Loop.run_until_complete
  File "uvloop/loop.pyx", line 1684, in create_server
  File "uvloop/loop.pyx", line 1116, in uvloop.loop.Loop._create_server
OSError: [Errno 48] error while attempting to bind on address ('0.0.0.0', 5005): address already in use
2019-11-08 16:09:33,810 [ERROR]  Unable to start server
Traceback (most recent call last):
  File "uvloop/loop.pyx", line 1112, in uvloop.loop.Loop._create_server
  File "uvloop/handles/streamserver.pyx", line 58, in uvloop.loop.UVStreamServer.listen
  File "uvloop/handles/streamserver.pyx", line 95, in uvloop.loop.UVStreamServer._fatal_error
OSError: [Errno 48] Address already in use

During handling of the above exception, another exception occurred:

Traceback (most recent call last):
  File "/anaconda3/envs/friday/lib/python3.6/site-packages/sanic/server.py", line 745, in serve
    http_server = loop.run_until_complete(server_coroutine)
  File "uvloop/loop.pyx", line 1451, in uvloop.loop.Loop.run_until_complete
  File "uvloop/loop.pyx", line 1684, in create_server
  File "uvloop/loop.pyx", line 1116, in uvloop.loop.Loop._create_server
OSError: [Errno 48] error while attempting to bind on address ('0.0.0.0', 5005): address already in use
2019-11-18 16:46:21,447 [ERROR]  Unable to start server
Traceback (most recent call last):
  File "uvloop/loop.pyx", line 1112, in uvloop.loop.Loop._create_server
  File "uvloop/handles/streamserver.pyx", line 58, in uvloop.loop.UVStreamServer.listen
  File "uvloop/handles/streamserver.pyx", line 95, in uvloop.loop.UVStreamServer._fatal_error
OSError: [Errno 48] Address already in use

During handling of the above exception, another exception occurred:

Traceback (most recent call last):
  File "/anaconda3/envs/friday/lib/python3.6/site-packages/sanic/server.py", line 745, in serve
    http_server = loop.run_until_complete(server_coroutine)
  File "uvloop/loop.pyx", line 1451, in uvloop.loop.Loop.run_until_complete
  File "uvloop/loop.pyx", line 1684, in create_server
  File "uvloop/loop.pyx", line 1116, in uvloop.loop.Loop._create_server
OSError: [Errno 48] error while attempting to bind on address ('0.0.0.0', 5005): address already in use
2019-11-18 16:46:41,443 [ERROR]  Unable to start server
Traceback (most recent call last):
  File "uvloop/loop.pyx", line 1112, in uvloop.loop.Loop._create_server
  File "uvloop/handles/streamserver.pyx", line 58, in uvloop.loop.UVStreamServer.listen
  File "uvloop/handles/streamserver.pyx", line 95, in uvloop.loop.UVStreamServer._fatal_error
OSError: [Errno 48] Address already in use

During handling of the above exception, another exception occurred:

Traceback (most recent call last):
  File "/anaconda3/envs/friday/lib/python3.6/site-packages/sanic/server.py", line 745, in serve
    http_server = loop.run_until_complete(server_coroutine)
  File "uvloop/loop.pyx", line 1451, in uvloop.loop.Loop.run_until_complete
  File "uvloop/loop.pyx", line 1684, in create_server
  File "uvloop/loop.pyx", line 1116, in uvloop.loop.Loop._create_server
OSError: [Errno 48] error while attempting to bind on address ('0.0.0.0', 5005): address already in use
2019-11-18 16:48:04,795 [ERROR]  Unable to start server
Traceback (most recent call last):
  File "uvloop/loop.pyx", line 1112, in uvloop.loop.Loop._create_server
  File "uvloop/handles/streamserver.pyx", line 58, in uvloop.loop.UVStreamServer.listen
  File "uvloop/handles/streamserver.pyx", line 95, in uvloop.loop.UVStreamServer._fatal_error
OSError: [Errno 48] Address already in use

During handling of the above exception, another exception occurred:

Traceback (most recent call last):
  File "/anaconda3/envs/friday/lib/python3.6/site-packages/sanic/server.py", line 745, in serve
    http_server = loop.run_until_complete(server_coroutine)
  File "uvloop/loop.pyx", line 1451, in uvloop.loop.Loop.run_until_complete
  File "uvloop/loop.pyx", line 1684, in create_server
  File "uvloop/loop.pyx", line 1116, in uvloop.loop.Loop._create_server
OSError: [Errno 48] error while attempting to bind on address ('0.0.0.0', 5005): address already in use
2019-11-18 16:53:39,595 [ERROR]  Unable to start server
Traceback (most recent call last):
  File "uvloop/loop.pyx", line 1112, in uvloop.loop.Loop._create_server
  File "uvloop/handles/streamserver.pyx", line 58, in uvloop.loop.UVStreamServer.listen
  File "uvloop/handles/streamserver.pyx", line 95, in uvloop.loop.UVStreamServer._fatal_error
OSError: [Errno 48] Address already in use

During handling of the above exception, another exception occurred:

Traceback (most recent call last):
  File "/anaconda3/envs/friday/lib/python3.6/site-packages/sanic/server.py", line 745, in serve
    http_server = loop.run_until_complete(server_coroutine)
  File "uvloop/loop.pyx", line 1451, in uvloop.loop.Loop.run_until_complete
  File "uvloop/loop.pyx", line 1684, in create_server
  File "uvloop/loop.pyx", line 1116, in uvloop.loop.Loop._create_server
OSError: [Errno 48] error while attempting to bind on address ('0.0.0.0', 5005): address already in use
2019-11-18 16:53:55,990 [ERROR]  Unable to start server
Traceback (most recent call last):
  File "uvloop/loop.pyx", line 1112, in uvloop.loop.Loop._create_server
  File "uvloop/handles/streamserver.pyx", line 58, in uvloop.loop.UVStreamServer.listen
  File "uvloop/handles/streamserver.pyx", line 95, in uvloop.loop.UVStreamServer._fatal_error
OSError: [Errno 48] Address already in use

During handling of the above exception, another exception occurred:

Traceback (most recent call last):
  File "/anaconda3/envs/friday/lib/python3.6/site-packages/sanic/server.py", line 745, in serve
    http_server = loop.run_until_complete(server_coroutine)
  File "uvloop/loop.pyx", line 1451, in uvloop.loop.Loop.run_until_complete
  File "uvloop/loop.pyx", line 1684, in create_server
  File "uvloop/loop.pyx", line 1116, in uvloop.loop.Loop._create_server
OSError: [Errno 48] error while attempting to bind on address ('0.0.0.0', 5005): address already in use
